<?xml version="1.0" encoding="utf-8"?>
<!-- This URDF was automatically created by SolidWorks to URDF Exporter! Originally created by Stephen Brawner (brawner@gmail.com) 
     Commit Version: 1.6.0-4-g7f85cfe  Build Version: 1.6.7995.38578
     For more information, please see http://wiki.ros.org/sw_urdf_exporter -->
<robot
  name="test_robot">
  <link
    name="base_link">
    <inertial>
      <origin
        xyz="0 0 0"
        rpy="0 0 0" />
      <mass
        value="32.2445875633999" />
      <inertia
        ixx="1.42366812493727"
        ixy="0.00117725941495782"
        ixz="0.0336818751080011"
        iyy="1.40774462598815"
        iyz="-0.00540818136662138"
        izz="0.250061638265402" />
    </inertial>
    <visual>
      <!-- <origin
        xyz="0 0 0"
        rpy="0 0 0" /> -->
      <geometry>
        <mesh
          filename="package://smrr_simulation/meshes/base_link.STL" />
      </geometry>
      <material
        name="">
        <color
          rgba="0.643137254901961 0.615686274509804 0.6 1" />
      </material>
    </visual>
    <collision>
      <!-- <origin
        xyz="0 0 0"
        rpy="0 0 0" /> -->
      <geometry>
        <mesh
          filename="package://smrr_simulation/meshes/base_link.STL" />
      </geometry>
    </collision>
  </link>
  <link
    name="right_wheel">
    <inertial>
      <!-- <origin
        xyz="3.0462E-06 6.7239E-06 -0.43311"
        rpy="0 0 0" /> -->
      <mass
        value="0.98982" />
      <inertia
        ixx="0.0016792"
        ixy="6.5317E-09"
        ixz="-1.6467E-07"
        iyy="0.0016793"
        iyz="-3.6346E-07"
        izz="0.0028869" />
    </inertial>
    <visual>
      <!-- <origin
        xyz="0 0 0"
        rpy="0 0 0" /> -->
      <geometry>
        <mesh
          filename="package://smrr_simulation/meshes/right_wheel.STL" />
      </geometry>
      <material
        name="">
        <color
          rgba="0.2 0.2 0.2 1" />
      </material>
    </visual>
    <collision>
      <!-- <origin
        xyz="0 0 0"
        rpy="0 0 0" /> -->
      <geometry>
        <mesh
          filename="package://smrr_simulation/meshes/right_wheel.STL" />
      </geometry>
    </collision>
  </link>
  <joint
    name="right_wheel_joint"
    type="continuous">
    <origin
      xyz="-0.0024494 0.2011 0.0184"
      rpy="-1.5708 0 0" />
    <parent
      link="base_link" />
    <child
      link="right_wheel" />
    <axis
      xyz="0 0 1" />
  </joint>
  <link
    name="left_wheel">
    <inertial>
      <!-- <origin
        xyz="-8.3868E-07 7.334E-06 0.031111"
        rpy="0 0 0" /> -->
      <mass
        value="0.98982" />
      <inertia
        ixx="0.0016793"
        ixy="-1.1203E-08"
        ixz="-4.5335E-08"
        iyy="0.0016792"
        iyz="3.9644E-07"
        izz="0.0028869" />
    </inertial>
    <visual>
      <!-- <origin
        xyz="0 0 0"
        rpy="0 0 0" /> -->
      <geometry>
        <mesh
          filename="package://smrr_simulation/meshes/left_wheel.STL" />
      </geometry>
      <material
        name="">
        <color
          rgba="0.2 0.2 0.2 1" />
      </material>
    </visual>
    <collision>
      <!-- <origin
        xyz="0 0 0"
        rpy="0 0 0" /> -->
      <geometry>
        <mesh
          filename="package://smrr_simulation/meshes/left_wheel.STL" />
      </geometry>
    </collision>
  </link>
  <joint
    name="left_wheel_joint"
    type="continuous">
    <!-- <origin
      xyz="-0.0024494 0.2011 0.0184"
      rpy="-1.5708 0 0" /> -->
    <parent
      link="base_link" />
    <child
      link="left_wheel" />
    <axis
      xyz="0 0 1" />
  </joint>
  <link
    name="front_caster">
    <inertial>
      <origin
        xyz="0.24255 9.9553E-05 -0.04"
        rpy="0 0 0" />
      <mass
        value="0.03351" />
      <inertia
        ixx="5.3617E-06"
        ixy="0"
        ixz="0"
        iyy="5.3617E-06"
        iyz="0"
        izz="5.3617E-06" />
    </inertial>
    <visual>
      <!-- <origin
        xyz="0 0 0"
        rpy="0 0 0" /> -->
      <geometry>
        <mesh
          filename="package://smrr_simulation/meshes/front_caster.STL" />
      </geometry>
      <material
        name="">
        <color
          rgba="0.53725 0.34902 0.33725 1" />
      </material>
    </visual>
    <collision>
      <!-- <origin
        xyz="0 0 0"
        rpy="0 0 0" /> -->
      <geometry>
        <mesh
          filename="package://smrr_simulation/meshes/front_caster.STL" />
      </geometry>
    </collision>
  </link>
  <joint
    name="front_caster_joint"
    type="continuous">
    <!-- <origin
      xyz="0 0 0"
      rpy="0 0 0" /> -->
    <parent
      link="base_link" />
    <child
      link="front_caster" />
    <axis
      xyz="1 0 0" />
  </joint>
  <link
    name="back_caster">
    <inertial>
      <!-- <origin
        xyz="-0.24745 9.9553E-05 -0.04"
        rpy="0 0 0" /> -->
      <mass
        value="0.03351" />
      <inertia
        ixx="5.3617E-06"
        ixy="0"
        ixz="0"
        iyy="5.3617E-06"
        iyz="0"
        izz="5.3617E-06" />
    </inertial>
    <visual>
      <!-- <origin
        xyz="0 0 0"
        rpy="0 0 0" /> -->
      <geometry>
        <mesh
          filename="package://smrr_simulation/meshes/back_caster.STL" />
      </geometry>
      <material
        name="Aluminium">
        <color
          rgba="0.53725 0.34902 0.33725 1" />
      </material>
    </visual>
    <collision>
      <!-- <origin
        xyz="0 0 0"
        rpy="0 0 0" /> -->
      <geometry>
        <mesh
          filename="package://smrr_simulation/meshes/back_caster.STL" />
      </geometry>
    </collision>
  </link>
  <joint
    name="back_caster_joint"
    type="continuous">
    <!-- <origin
      xyz="0 0 0"
      rpy="0 0 0" /> -->
    <parent
      link="base_link" />
    <child
      link="back_caster" />
    <axis
      xyz="1 0 0" />
  </joint>
</robot>